Requirement already satisfied: pip in /Users/mac/Library/Application Support/pypoetry/venv/lib/python3.12/site-packages (24.0)
Collecting pip
  Downloading pip-24.1.1-py3-none-any.whl.metadata (3.6 kB)
Downloading pip-24.1.1-py3-none-any.whl (1.8 MB)
   ━━━━━━━━━━━━━━━━━━━━━━━━━━━━━━╸          1.4/1.8 MB 381.6 kB/s eta 0:00:02
ERROR: Exception:
Traceback (most recent call last):
  File "/Users/mac/Library/Application Support/pypoetry/venv/lib/python3.12/site-packages/pip/_vendor/urllib3/response.py", line 438, in _error_catcher
    yield
  File "/Users/mac/Library/Application Support/pypoetry/venv/lib/python3.12/site-packages/pip/_vendor/urllib3/response.py", line 561, in read
    data = self._fp_read(amt) if not fp_closed else b""
           ^^^^^^^^^^^^^^^^^^
  File "/Users/mac/Library/Application Support/pypoetry/venv/lib/python3.12/site-packages/pip/_vendor/urllib3/response.py", line 527, in _fp_read
    return self._fp.read(amt) if amt is not None else self._fp.read()
           ^^^^^^^^^^^^^^^^^^
  File "/Users/mac/Library/Application Support/pypoetry/venv/lib/python3.12/site-packages/pip/_vendor/cachecontrol/filewrapper.py", line 98, in read
    data: bytes = self.__fp.read(amt)
                  ^^^^^^^^^^^^^^^^^^^
  File "/usr/local/Cellar/python@3.12/3.12.2_1/Frameworks/Python.framework/Versions/3.12/lib/python3.12/http/client.py", line 479, in read
    s = self.fp.read(amt)
        ^^^^^^^^^^^^^^^^^
  File "/usr/local/Cellar/python@3.12/3.12.2_1/Frameworks/Python.framework/Versions/3.12/lib/python3.12/socket.py", line 707, in readinto
    return self._sock.recv_into(b)
           ^^^^^^^^^^^^^^^^^^^^^^^
  File "/usr/local/Cellar/python@3.12/3.12.2_1/Frameworks/Python.framework/Versions/3.12/lib/python3.12/ssl.py", line 1252, in recv_into
    return self.read(nbytes, buffer)
           ^^^^^^^^^^^^^^^^^^^^^^^^^
  File "/usr/local/Cellar/python@3.12/3.12.2_1/Frameworks/Python.framework/Versions/3.12/lib/python3.12/ssl.py", line 1104, in read
    return self._sslobj.read(len, buffer)
           ^^^^^^^^^^^^^^^^^^^^^^^^^^^^^^
TimeoutError: The read operation timed out

During handling of the above exception, another exception occurred:

Traceback (most recent call last):
  File "/Users/mac/Library/Application Support/pypoetry/venv/lib/python3.12/site-packages/pip/_internal/cli/base_command.py", line 180, in exc_logging_wrapper
    status = run_func(*args)
             ^^^^^^^^^^^^^^^
  File "/Users/mac/Library/Application Support/pypoetry/venv/lib/python3.12/site-packages/pip/_internal/cli/req_command.py", line 245, in wrapper
    return func(self, options, args)
           ^^^^^^^^^^^^^^^^^^^^^^^^^
  File "/Users/mac/Library/Application Support/pypoetry/venv/lib/python3.12/site-packages/pip/_internal/commands/install.py", line 377, in run
    requirement_set = resolver.resolve(
                      ^^^^^^^^^^^^^^^^^
  File "/Users/mac/Library/Application Support/pypoetry/venv/lib/python3.12/site-packages/pip/_internal/resolution/resolvelib/resolver.py", line 179, in resolve
    self.factory.preparer.prepare_linked_requirements_more(reqs)
  File "/Users/mac/Library/Application Support/pypoetry/venv/lib/python3.12/site-packages/pip/_internal/operations/prepare.py", line 552, in prepare_linked_requirements_more
    self._complete_partial_requirements(
  File "/Users/mac/Library/Application Support/pypoetry/venv/lib/python3.12/site-packages/pip/_internal/operations/prepare.py", line 467, in _complete_partial_requirements
    for link, (filepath, _) in batch_download:
  File "/Users/mac/Library/Application Support/pypoetry/venv/lib/python3.12/site-packages/pip/_internal/network/download.py", line 183, in __call__
    for chunk in chunks:
  File "/Users/mac/Library/Application Support/pypoetry/venv/lib/python3.12/site-packages/pip/_internal/cli/progress_bars.py", line 53, in _rich_progress_bar
    for chunk in iterable:
  File "/Users/mac/Library/Application Support/pypoetry/venv/lib/python3.12/site-packages/pip/_internal/network/utils.py", line 63, in response_chunks
    for chunk in response.raw.stream(
  File "/Users/mac/Library/Application Support/pypoetry/venv/lib/python3.12/site-packages/pip/_vendor/urllib3/response.py", line 622, in stream
    data = self.read(amt=amt, decode_content=decode_content)
           ^^^^^^^^^^^^^^^^^^^^^^^^^^^^^^^^^^^^^^^^^^^^^^^^^
  File "/Users/mac/Library/Application Support/pypoetry/venv/lib/python3.12/site-packages/pip/_vendor/urllib3/response.py", line 560, in read
    with self._error_catcher():
  File "/usr/local/Cellar/python@3.12/3.12.2_1/Frameworks/Python.framework/Versions/3.12/lib/python3.12/contextlib.py", line 158, in __exit__
    self.gen.throw(value)
  File "/Users/mac/Library/Application Support/pypoetry/venv/lib/python3.12/site-packages/pip/_vendor/urllib3/response.py", line 443, in _error_catcher
    raise ReadTimeoutError(self._pool, None, "Read timed out.")
pip._vendor.urllib3.exceptions.ReadTimeoutError: HTTPSConnectionPool(host='files.pythonhosted.org', port=443): Read timed out.

Traceback:

  File "<stdin>", line 923, in main
  File "<stdin>", line 560, in run
  File "<stdin>", line 581, in install
  File "/usr/local/Cellar/python@3.12/3.12.2_1/Frameworks/Python.framework/Versions/3.12/lib/python3.12/contextlib.py", line 137, in __enter__
    return next(self.gen)
           ^^^^^^^^^^^^^^
  File "<stdin>", line 653, in make_env
  File "<stdin>", line 639, in make_env
  File "<stdin>", line 352, in make
  File "<stdin>", line 375, in pip
  File "<stdin>", line 372, in python
  File "<stdin>", line 365, in run
